[17:39:50.850900] SeBS-b8ab Created experiment output at /home/kalm/serverless-benchmarks/results-local-20241029_173949/311.compression
[17:39:51.197232] LocalResources-aed9 Using user-provided configuration of storage for local containers.
[17:39:51.247251] Local-b95f Using existing deployment local-0aa31c18 that matches prefix local!
[17:39:51.248990] Benchmark-c365 Building benchmark 311.compression. Reason: no cached code package.
[17:39:51.255639] Local-b95f Function size 0.003906 MB
[17:39:51.256510] Benchmark-c365 Created code package (source hash: 3a4d8dfccd9c08b9d413c6362c382eca), for run on local with python:3.7
[17:39:51.260869] Local-b95f Creating new function! Reason: function 311.compression-python-3.7 not found in cache.
[17:39:53.218096] Local-b95f Started 311.compression-python-3.7 function at container 88a59f8851fe648a7f705eba4080d5fa5f200c723f40c74bc77b4fbe809ec551 , running on 172.17.0.7:9000
[17:39:53.272004] minio.Minio-97a8 Using existing bucket sebs-benchmarks-local-0aa31c18 for benchmarks
[17:39:56.071895] SeBS-b8ab Beginning repetition 1/50
[17:39:56.082563] Local.HTTPTrigger-de1b Invoke function 172.17.0.7:9000
[17:39:56.309209] Local.HTTPTrigger-de1b Invocation on URL 172.17.0.7:9000 failed!
[17:39:56.314945] Local.HTTPTrigger-de1b Output: 
    <!DOCTYPE HTML PUBLIC "-//IETF//DTD HTML 2.0//EN">
    <html>
        <head>
            <title>Error: 500 Internal Server Error</title>
            <style type="text/css">
              html {background-color: #eee; font-family: sans-serif;}
              body {background-color: #fff; border: 1px solid #ddd;
                    padding: 15px; margin: 15px;}
              pre {background-color: #eee; border: 1px solid #ddd; padding: 5px;}
            </style>
        </head>
        <body>
            <h1>Error: 500 Internal Server Error</h1>
            <p>Sorry, the requested URL <tt>&#039;http://172.17.0.7:9000/&#039;</tt>
               caused an error:</p>
            <pre>Internal Server Error</pre>
              <h2>Exception:</h2>
              <pre>AttributeError(&quot;&#039;Minio&#039; object has no attribute &#039;list_objects_v2&#039;&quot;)</pre>
              <h2>Traceback:</h2>
              <pre>Traceback (most recent call last):
  File &quot;/usr/local/lib/python3.7/site-packages/bottle.py&quot;, line 995, in _handle
    out = route.call(**args)
  File &quot;/usr/local/lib/python3.7/site-packages/bottle.py&quot;, line 2025, in wrapper
    rv = callback(*a, **ka)
  File &quot;/sebs/server.py&quot;, line 23, in process_request
    ret = function.handler(request.json)
  File &quot;/function/function/function.py&quot;, line 29, in handler
    client.download_directory(bucket, os.path.join(input_prefix, key), download_path)
  File &quot;/function/function/storage.py&quot;, line 40, in download_directory
    objects = self.client.list_objects_v2(bucket, prefix, recursive=True)
AttributeError: &#039;Minio&#039; object has no attribute &#039;list_objects_v2&#039;
</pre>
        </body>
    </html>

ERROR:root:Failed invocation of function! Output: 
    <!DOCTYPE HTML PUBLIC "-//IETF//DTD HTML 2.0//EN">
    <html>
        <head>
            <title>Error: 500 Internal Server Error</title>
            <style type="text/css">
              html {background-color: #eee; font-family: sans-serif;}
              body {background-color: #fff; border: 1px solid #ddd;
                    padding: 15px; margin: 15px;}
              pre {background-color: #eee; border: 1px solid #ddd; padding: 5px;}
            </style>
        </head>
        <body>
            <h1>Error: 500 Internal Server Error</h1>
            <p>Sorry, the requested URL <tt>&#039;http://172.17.0.7:9000/&#039;</tt>
               caused an error:</p>
            <pre>Internal Server Error</pre>
              <h2>Exception:</h2>
              <pre>AttributeError(&quot;&#039;Minio&#039; object has no attribute &#039;list_objects_v2&#039;&quot;)</pre>
              <h2>Traceback:</h2>
              <pre>Traceback (most recent call last):
  File &quot;/usr/local/lib/python3.7/site-packages/bottle.py&quot;, line 995, in _handle
    out = route.call(**args)
  File &quot;/usr/local/lib/python3.7/site-packages/bottle.py&quot;, line 2025, in wrapper
    rv = callback(*a, **ka)
  File &quot;/sebs/server.py&quot;, line 23, in process_request
    ret = function.handler(request.json)
  File &quot;/function/function/function.py&quot;, line 29, in handler
    client.download_directory(bucket, os.path.join(input_prefix, key), download_path)
  File &quot;/function/function/storage.py&quot;, line 40, in download_directory
    objects = self.client.list_objects_v2(bucket, prefix, recursive=True)
AttributeError: &#039;Minio&#039; object has no attribute &#039;list_objects_v2&#039;
</pre>
        </body>
    </html>

Traceback (most recent call last):
  File "/home/kalm/serverless-benchmarks/sebs/faas/function.py", line 213, in _http_invoke
    output = json.loads(data.getvalue())
             ^^^^^^^^^^^^^^^^^^^^^^^^^^^
  File "/usr/lib/python3.12/json/__init__.py", line 346, in loads
    return _default_decoder.decode(s)
           ^^^^^^^^^^^^^^^^^^^^^^^^^^
  File "/usr/lib/python3.12/json/decoder.py", line 337, in decode
    obj, end = self.raw_decode(s, idx=_w(s, 0).end())
               ^^^^^^^^^^^^^^^^^^^^^^^^^^^^^^^^^^^^^^
  File "/usr/lib/python3.12/json/decoder.py", line 355, in raw_decode
    raise JSONDecodeError("Expecting value", s, err.value) from None
json.decoder.JSONDecodeError: Expecting value: line 2 column 5 (char 5)

During handling of the above exception, another exception occurred:

Traceback (most recent call last):
  File "/home/kalm/serverless-benchmarks/./sebs.py", line 30, in __call__
    return self.main(*args, **kwargs)
           ^^^^^^^^^^^^^^^^^^^^^^^^^^
  File "/home/kalm/serverless-benchmarks/python-venv/lib/python3.12/site-packages/click/core.py", line 1078, in main
    rv = self.invoke(ctx)
         ^^^^^^^^^^^^^^^^
  File "/home/kalm/serverless-benchmarks/python-venv/lib/python3.12/site-packages/click/core.py", line 1688, in invoke
    return _process_result(sub_ctx.command.invoke(sub_ctx))
                           ^^^^^^^^^^^^^^^^^^^^^^^^^^^^^^^
  File "/home/kalm/serverless-benchmarks/python-venv/lib/python3.12/site-packages/click/core.py", line 1688, in invoke
    return _process_result(sub_ctx.command.invoke(sub_ctx))
                           ^^^^^^^^^^^^^^^^^^^^^^^^^^^^^^^
  File "/home/kalm/serverless-benchmarks/python-venv/lib/python3.12/site-packages/click/core.py", line 1434, in invoke
    return ctx.invoke(self.callback, **ctx.params)
           ^^^^^^^^^^^^^^^^^^^^^^^^^^^^^^^^^^^^^^^
  File "/home/kalm/serverless-benchmarks/python-venv/lib/python3.12/site-packages/click/core.py", line 783, in invoke
    return __callback(*args, **kwargs)
           ^^^^^^^^^^^^^^^^^^^^^^^^^^^
  File "/home/kalm/serverless-benchmarks/./sebs.py", line 72, in wrapper
    return func(*args, **kwargs)
           ^^^^^^^^^^^^^^^^^^^^^
  File "/home/kalm/serverless-benchmarks/./sebs.py", line 103, in wrapper
    return func(*args, **kwargs)
           ^^^^^^^^^^^^^^^^^^^^^
  File "/home/kalm/serverless-benchmarks/./sebs.py", line 263, in invoke
    ret = trigger.sync_invoke(input_config)
          ^^^^^^^^^^^^^^^^^^^^^^^^^^^^^^^^^
  File "/home/kalm/serverless-benchmarks/sebs/local/function.py", line 24, in sync_invoke
    return self._http_invoke(payload, self.url)
           ^^^^^^^^^^^^^^^^^^^^^^^^^^^^^^^^^^^^
  File "/home/kalm/serverless-benchmarks/sebs/faas/function.py", line 237, in _http_invoke
    raise RuntimeError(f"Failed invocation of function! Output: {data.getvalue().decode()}")
RuntimeError: Failed invocation of function! Output: 
    <!DOCTYPE HTML PUBLIC "-//IETF//DTD HTML 2.0//EN">
    <html>
        <head>
            <title>Error: 500 Internal Server Error</title>
            <style type="text/css">
              html {background-color: #eee; font-family: sans-serif;}
              body {background-color: #fff; border: 1px solid #ddd;
                    padding: 15px; margin: 15px;}
              pre {background-color: #eee; border: 1px solid #ddd; padding: 5px;}
            </style>
        </head>
        <body>
            <h1>Error: 500 Internal Server Error</h1>
            <p>Sorry, the requested URL <tt>&#039;http://172.17.0.7:9000/&#039;</tt>
               caused an error:</p>
            <pre>Internal Server Error</pre>
              <h2>Exception:</h2>
              <pre>AttributeError(&quot;&#039;Minio&#039; object has no attribute &#039;list_objects_v2&#039;&quot;)</pre>
              <h2>Traceback:</h2>
              <pre>Traceback (most recent call last):
  File &quot;/usr/local/lib/python3.7/site-packages/bottle.py&quot;, line 995, in _handle
    out = route.call(**args)
  File &quot;/usr/local/lib/python3.7/site-packages/bottle.py&quot;, line 2025, in wrapper
    rv = callback(*a, **ka)
  File &quot;/sebs/server.py&quot;, line 23, in process_request
    ret = function.handler(request.json)
  File &quot;/function/function/function.py&quot;, line 29, in handler
    client.download_directory(bucket, os.path.join(input_prefix, key), download_path)
  File &quot;/function/function/storage.py&quot;, line 40, in download_directory
    objects = self.client.list_objects_v2(bucket, prefix, recursive=True)
AttributeError: &#039;Minio&#039; object has no attribute &#039;list_objects_v2&#039;
</pre>
        </body>
    </html>

